Workbook

Sheet DATA_SURAT_PELANTIKAN
A1: Bil | B1: Tahun | C1: Tarikh | D1: Kepada (pengerusi) | E1: Penolong Pengerusi | F1: panel 1 | G1: panel 2 | H1: alamat / Fakulti | I1: Pengerusi/Panel (Fakulti lain) | J1: panel (Fakulti lain) | K1: Fakulti | L1: Tajuk (SEMULA) | M1: Tajuk | N1: Tajuk (re-Proposal Defense) | O1: Panggilan hormat | P1: Panggilan hormat_2 | Q1: Punca kuasa | R1: Isi surat 1 | S1: isi surat 2 | T1: Program | U1: Bidang | V1: Nama Pelajar | W1: No. Matrik | X1: Tajuk Proposal | Y1: Tarikh | Z1: Masa | AA1: Tempat | AB1: sk 1 | AC1: sk 2 | AD1: sk 3 | AE1: Nota | AF1: Rujukan Surat Pelantikan | AG1: Tarikh Surat | AH1: Tajuk Penterjemah | AI1: Kelulusan Khidmat Penterjemah (We are glad/ We regret) | AJ1: Kelulusan (SUCCESSFUL/ UNSUCCESSFUL) | AK1: Kategori Penterjemahan
A2: 1 | C2: MEI | D2: Dr. Shah Iskandar Fahmie bin Ramlee | E2: Dr. Nur Syakirah binti Ahmad | F2: Prof. Dr. Raja Suzana binti Raja Kasim | G2: Dr. Norzalizah binti Bahari | H2: Fakulti Keusahawanan dan Perniagaan | L2: SEMULA | N2: re-PROPOSAL DEFENSE | O2: YBhg. Prof./Dr. | P2: YBhg. Prof./Dr. | Q2: Mesyuarat Jawatankuasa Pascasiswazah Bil. 4/2024 (kali ke-45) | R2: Semula | S2: re-Proposal Defense | T2: Doktor Falsafah | U2: Keusahawanan | V2: Abu Bakar bin Busmah | W2: A21E0127P | X2: Kesan Kompetensi Keusahawanan Terhadap Prestasi Koperasi Sekolah Melalui Tingkah Laku Kepimpinan Transformasi Anggota Lembaga Koperasi Sekolah di Malaysia | Y2: 24 Jun 2024 (Isnin) | Z2: 11.00 pagi | AA2: Platform Zoom (pautan akan dimaklumkan kemudian) | AB2: 1) Prof. Dr. Roselina binti Ahmad Saufi (Penyelia Utama) | AC2: 2) Dr. Noor Raihani binti Zainol (Penyelia Bersama)
A3: 2 | C3: MEI | D3: Dr. Syarizal bin Abdul Rahim | E3: Dr. Siti Som binti Husin | F3: Prof. Madya Dr. Dzulkifli bin Mukhtar | G3: Prof. Madya Dr. Mohd Nazri bin Zakaria | H3: Fakulti Keusahawanan dan Perniagaan | L3: SEMULA | N3: re-PROPOSAL DEFENSE | O3: YBrs. Prof. Madya/Dr. | P3: YBrs. Prof. Madya/Dr. | Q3: Mesyuarat Jawatankuasa Pascasiswazah Bil. 4/2024 (kali ke-45) | R3: Semula | S3: re-Proposal Defence | T3: Doktor Falsafah | U3: Pengurusan | V3: Chen Li | W3: A20E0214F | X3: The Effectiveness of Performance Management Module (PMM) on Nurse Performance with Moderating Effect of Willingness to Use HMIS Among Nurses in Hunan Public Hospitals | Y3: 28 Mei 2024 (selasa) | Z3: 10.30 pagi | AA3: Platform Zoom (pautan akan dimaklumkan kemudian) | AB3: 1) Prof. Madya Dr. Muhamad Saufi bin Che Rusuli (Penyelia Utama) | AC3: 2) Prof. Madya Dr. Noorshella binti Che Nawi (Jawatankuasa Penyeliaan) | AD3: 3) Dr. wan Mohd Nazdrol bin Wan Mohd Nasir (Jawatankuasa Penyeliaan)
A4: 3 | C4: MEI | D4: Prof. Madya. Dr. Mohd Zulkifli bin Muhammad | E4: Dr. Siti Salwani binti Abdullah | F4: Dr. Siti Fariha binti Muhamad | G4: Dr. Muhammad Jaffri bin Mohd Nasir | H4: Fakulti Keusahawanan dan Perniagaan | N4: PROPOSAL DEFENSE | O4: YBrs. Prof. Madya/Dr. | P4: YBrs. Prof. Madya/Dr. | Q4: Mesyuarat Jawatankuasa Pascasiswazah Bil. 4/2024 (kali ke-45) | S4: Proposal Defense | T4: Sarjana | U4: Kewangan | V4: Nursyahiyatul Anis binti Othman | W4: A23D053F | X4: Asseccing A Comprehensive Cost Analysis on Meliodosis in Northern Malaysia | Y4: 12 Jun 2024 (Rabu) | Z4: 2.30 petang | AA4: Platform Zoom (pautan akan dimaklumkan kemudian) | AB4: 1) Dr. Mardhiah binti Kamaruddin (Penyelia Utama) | AC4: 2) Prof. Madya Dr. Hazriah binti Hasan (Penyelia Bersama)
A5: 4 | C5: MEI | D5: Dr. Syarizal bin Abdul Rahim | E5: Dr. Norhafifah binti Samsudin | F5: Prof. Madya Dr. Wan Farha binti Wan Zulkiffli | G5: Dr. Mohd Ikhwan bin Aziz | H5: Fakulti Keusahawanan dan Perniagaan | N5: PROPOSAL DEFENSE | O5: YBrs. Prof. Madya/Dr. | P5: YBrs. Prof. Madya/Dr. | Q5: Mesyuarat Jawatankuasa Pascasiswazah Bil. 4/2024 (kali ke-45) | S5: Proposal Defense | T5: Doktor Falsafah | U5: Pengurusan | V5: Chen Zaidie | W5: A20E054F | X5: Exploring the Enduring Influence of Perceived of External Control and Computer Playfulness towards Behavioral Intention on User Adoption of Banking Mobile Applications in Hangzhou City Commercial Bank: The Mediating effect of Perceived Ease of Use | Y5: 27 Mei 2024 (Isnin) | Z5: 9.30 pagi | AA5: Platform Zoom (pautan akan dimaklumkan kemudian) | AB5: 1) Dr. Fatihah binti Mohd (Penyelia Utama) | AC5: 2) Dr. Nur Ain Ayunni binti Sabri (Penyelia Bersama)
A6: 5 | C6: MEI | D6: Prof. Madya Dr. Dzulkifli bin Mukhtar | E6: Dr. Siti Rohana binti Mohamad | F6: Dr. Zaminor binti Zamzamir @ Zamzamin | G6: Dr. Ahmad Ridhuwan bin Abdullah | H6: Fakulti Keusahawanan dan Perniagaan | N6: PROPOSAL DEFENSE | O6: YBrs. Prof. Madya/Dr. | P6: YBrs. Prof. Madya/Dr. | Q6: Mesyuarat Jawatankuasa Pascasiswazah Bil. 4/2024 (kali ke-45) | S6: Proposal Defense | T6: Doktor Falsafah | U6: Kewangan | V6: Ma Jianmei | W6: A21E013F | X6: The Impact of Digital Inclusive Finance on Financing Constraints of Small and Medium Sized Enterprises in China. | Y6: 29 Mei 2024 (Rabu) | Z6: 9.30 pagi | AA6: Platform Zoom (pautan akan dimaklumkan kemudian) | AB6: 1) Dr. Noormariana binti Mohd Din (Penyelia Utama)
A7: 6 | C7: JUN | D7: Prof. Madya Dr. Dzulkifli bin Mukhtar | E7: Dr. Nur Fadiah binti Mohd Zawawi | F7: Prof. Dr. Mohd Nor Hakimin bin Yusoff | G7: Prof. Dr. Mohd Rafi bin Yaacob | H7: Fakulti Keusahawanan dan Perniagaan | N7: PROPOSAL DEFENSE | O7: YBhg. Prof. | P7: YBhg. Prof. | Q7: Mesyuarat Jawatankuasa Pascasiswazah Bil. 4/2024 (kali ke-45) | S7: Proposal Defense | T7: Doktor Falsafah | U7: Perakaunan | V7: Syukry Hadi | W7: A19E0039F | X7: Determinants of Job Performance Among Financial Employees in Indonesia Private Hospital : The Role of Intrapreneurship as Mediator and Psychological Ownership as Moderator | Y7: 8 Julai 2024 (Isnin) | Z7: 10.00 pagi | AA7: Platform Zoom (pautan akan dimaklumkan kemudian) | AB7: 1) Prof. Dato’ Dr. Razli bin Che Razak (Penyelia Utama)
A8: 7 | C8: MEI | D8: Prof. Dr. Balakrishnan a/l Parasuraman | E8: Dr. Norzalizah binti Bahari | F8: Prof. Dr. Mohd Nor Hakimin bin Yusoff | G8: Prof. Madya Dr. Mohd Nazri bin Zakaria | H8: Fakulti Keusahawanan dan Perniagaan | N8: PROPOSAL DEFENSE | O8: YBhg. Prof. | P8: YBhg. Prof. | Q8: Mesyuarat Jawatankuasa Pascasiswazah Bil. 4/2024 (kali ke-45) | S8: Proposal Defense | T8: Doktor Falsafah | U8: Pengurusan | V8: Muhammad Fikry Hadi | W8: A19E0023F | X8: Pengaruh Kepimpinan Transformasi dan Komitmen Organisasi Terhadap Prestasi Kerja Pensyarah Universiti Muhammadiyah di Indonesia : Kesan Pengantara Kepuasan Kerja dan Penyederhanaan Kepimpinan Rohani | Y8: 6 Jun 2024 (Khamis) | Z8: 9.30 pagi | AA8: Platform Zoom (pautan akan dimaklumkan kemudian) | AB8: 1) Prof. Dato’ Dr. Razli bin Che Razak (Penyelia Utama) | AC8: 2) Dr. Nurul Hafizah binti Mohd Yasin (Penyelia Bersama)
A9: 8 | C9: MEI | D9: Dr. Nur Syafiqah binti A. Samad | E9: Pn. Nik Noorhazila binti Nik Mud | F9: Dr. Nor Asma binti Ahmad | G9: Dr. Zaminor binti Zamzamir @ Zamzamin | H9: Fakulti Keusahawanan dan Perniagaan | N9: PRA PEPERIKSAAN LISAN (PRE VIVA) | O9: YBrs. Dr./Puan | P9: YBrs. Dr./Puan | Q9: Mesyuarat Jawatankuasa Pascasiswazah Bil. 4/2024 (kali ke-45) | S9: Pra Peperiksaan Lisan (Pre Viva) | T9: Doktor Falsafah | U9: Kewangan | V9: Nurza binti Mohamed Yusoff | W9: A18E025F | X9: The Nexus of Financial Development, Employment, and Economic Growth in Developing Countries: The Role of Minimum Wage | Y9: 9 Jun 2024 (Ahad) | Z9: 2.30 petang | AA9: Platform Zoom (pautan akan dimaklumkan kemudian) | AB9: 1) Dr Nurnaddia binti Nordin (Penyelia Utama) | AC9: 2) Dr. Nurhaiza binti Nordin (Penyelia Bersama)
A10: 9 | C10: MEI | D10: Dr. Azira Hanani binti Berahim @ Ab Rahman | E10: Pn. Nik Madeeha binti Nik Mohd Munir | F10: Dr. Nor Asma binti Ahmad | G10: Dr. Zaminor binti Zamzamir @ Zamzamin | H10: Fakulti Keusahawanan dan Perniagaan | N10: PRA PEPERIKSAAN LISAN (PRE VIVA) | O10: YBrs. Dr./Puan | P10: YBrs. Dr./Puan | Q10: Mesyuarat Jawatankuasa Pascasiswazah Bil. 4/2024 (kali ke-45) | S10: Pra Peperiksaan Lisan (Pre Viva) | T10: Doktor Falsafah | U10: Kewangan | V10: Han Yue | W10: A20E0110F | X10: Evaluation of Macroeconomic Models for Financial Stability Analysis: A Case Study of Financial Market in China | Y10: 12 Jun 2024 (Rabu) | Z10: 11.00 pagi | AA10: Platform Zoom (pautan akan dimaklumkan kemudian) | AB10: 1) Dr Nurnaddia binti Nordin (Penyelia Utama) | AC10: 2) Dr. Nurhaiza binti Nordin (Penyelia Bersama)
A11: 10 | C11: MEI | D11: Prof. Madya. Dr. Mohd Zulkifli bin Muhammad | E11: Pn. Aimi Nadia binti Ibrahim @ Zakaria | F11: Prof. Madya Dr. Muhamad Saufi bin Che Rusuli | G11: Prof. Madya Dr. Noorshella binti Che Nawi | H11: Fakulti Keusahawanan dan Perniagaan | N11: PRA PEPERIKSAAN LISAN (PRE VIVA) | O11: YBrs. Prof. Madya/puan | P11: YBrs. Prof. Madya/puan | Q11: Mesyuarat Jawatankuasa Pascasiswazah Bil. 4/2024 (kali ke-45) | S11: Pra Peperiksaan Lisan (Pre Viva) | T11: Doktor Falsafah | U11: Peruncitan | V11: Haidong Zhang | W11: A20E002F | X11: The Relationship Between The Big Data Analysis Capability, External Knowledge Search and Omni-Channel Marketing on Firm Performance in China | Y11: 11 Jun 2024 (Selasa) | Z11: 11.00 pagi | AA11: Platform Zoom (pautan akan dimaklumkan kemudian) | AB11: 1) Prof. Madya Ts. Dr. Zailani bin Abdullah (Penyelia Utama)
A12: 11 | C12: MEI | D12: Prof. Madya Dr. Mohd Nazri bin Zakaria | E12: Dr. Syamsuriana binti Sidek | F12: Prof. Dr. Mohd Rafi bin Yaacob | G12: Prof. Madya Ts. Dr. Zuraimi bin Abdul Aziz | H12: Fakulti Keusahawanan dan Perniagaan | L12: SESI PENILAIAN SEMULA | N12: PRA PEPERIKSAAN LISAN (re-PRE VIVA) | O12: YBhg. Prof./Prof. Madya/Dr. | P12: YBhg. Prof./Prof. Madya/Dr. | Q12: Mesyuarat Jawatankuasa Pascasiswazah Bil. 4/2024 (kali ke-45) | R12: Sesi Penilaian Semula | S12: Pra Peperiksaan Lisan (re-Pre Viva) | T12: Doktor Falsafah | U12: Keusahawanan | V12: Fadhilahanim Aryani binti Abdullah | W12: C14E008P | X12: Innovation Competency and Innovation Capability on SME’s Innovation Performance in Malaysia Health Tourism Industry: Moderating Effects of Digital Technology Diffusion | Y12: 10 Julai 2024 (Rabu) | Z12: 9.30 pagi | AA12: Platform Zoom (pautan akan dimaklumkan kemudian) | AB12: 1) Prof. Dato' Dr. Nik Maheran binti Nik Muhammad (Penyelia Utama)
A13: 12 | C13: MEI | D13: Prof. Madya Dr. Mohd Nazri bin Zakaria | E13: Dr. Syamsuriana binti Sidek | F13: Prof. Dr. Raja Suzana binti Raja Kasim | G13: Dr. Nor Hafiza binti Othman | H13: Fakulti Keusahawanan dan Perniagaan | N13: PRA PEPERIKSAAN LISAN (PRE VIVA) | O13: YBhg. Prof./Prof. Madya/Dr. | P13: YBhg. Prof./Prof. Madya/Dr. | S13: Pra Peperiksaan Lisan (Pre Viva) | T13: Doktor Falsafah | U13: Keusahawanan | V13: Reni Mutiarani Saraswati | W13: A20E0179F | X13: Social Entrepreneurial Orientation on Sustainability Performance Among social Business Organizations in Indonesia | Y13: 5 Jun 2024 (Rabu) | Z13: 11.00 pagi | AA13: Platform Zoom (pautan akan dimaklumkan kemudian) | AB13: 1) Dr. Noor Raihani binti Zainol (Penyelia Utama) | AC13: 2) Dr. Suhaila binti Abdul Kadir (Penyelia Bersama)
A14: 13 | C14: JUN | D14: Prof. Madya Dr. Noorul Azwin binti Md Nasir | E14: Dr. Nor Asma binti Ahmad | F14: Dr. Tahirah binti Abdullah | G14: Dr. Mohd Rushdan bin Yasoa’ | H14: Fakulti Keusahawanan dan Perniagaan | N14: PENILAIAN CADANGAN PENYELIDIKAN (PROPOSAL DEFENSE) | O14: YBrs. Prof. Madya/Dr. | P14: YBrs. Prof. Madya/Dr. | Q14: Mesyuarat Jawatankuasa Pascasiswazah Bil. 5/2024 (kali ke-46) | S14: Penilaian Cadangan Penyelidikan (Proposal Defense) | T14: Sarjana | U14: Pengurusan | V14: Huang Jiayi | W14: A22D106F | X14: Green Accounting by SME in China: An Application of Theory of Planned and Behaviour | Y14: 12 Ogos 2024 (Isnin) | Z14: 10.00 pagi | AA14: Platform Zoom (pautan akan dimaklumkan kemudian) | AB14: 1) Dr. Siti Afiqah binti Zainuddin (Penyelia Utama) | AE14: Pengerusi - Prof. Madya Dr. Azwan bin Abdullah (Tukar) Panel 1 - PM. Dr. Nazri bin Zakaria (Tukar)
A15: 14 | C15: JUN | D15: Dr. Kasmaruddin bin Che Hussin | E15: En. Mohamed Ariff bin Abdul Rahman | F15: Prof. Dr. Mohd Rafi bin Yaacob | G15: Dr. Tahirah binti Abdullah | H15: Fakulti Keusahawanan dan Perniagaan | N15: PENILAIAN CADANGAN PENYELIDIKAN (PROPOSAL DEFENSE) | O15: YBhg. Prof./Prof. Madya/Dr. | P15: YBhg. Prof./Prof. Madya/Dr. | Q15: Mesyuarat Jawatankuasa Pascasiswazah Bil. 5/2024 (kali ke-46) | S15: Penilaian Cadangan Penyelidikan (Proposal Defense) | T15: Doktor Falsafah | U15: Perakaunan | V15: Wu Shuangshuang | W15: A21E054F | X15: Study on the Effect of Preferential Tax Policies on Science and Technology Capital | Y15: 14 Julai 2024 (Ahad) | Z15: 10.00 pagi | AA15: Platform Zoom (pautan akan dimaklumkan kemudian) | AB15: 1) Prof. Dr. Mohd Nor Hakimin bin Yusof (Penyelia Utama)
A16: 15 | C16: JUN | D16: Dr. Suhaila binti Abdul Kadir | E16: Dr. Norzalizah binti Bahari | F16: Prof. Madya Dr. Dzulkifli bin Mukhtar | G16: Dr. Nor Hafiza binti Othman | H16: Fakulti Keusahawanan dan Perniagaan | N16: PRA PEPERIKSAAN LISAN (PRE VIVA) | O16: YBrs. Prof. Madya/Dr. | P16: YBrs. Prof. Madya/Dr. | Q16: Mesyuarat Jawatankuasa Pascasiswazah Bil. 5/2024 (kali ke-46) | S16: Pra Peperiksaan Lisan (Pre Viva) | T16: Doktor Falsafah | U16: Pengurusan | V16: Nor Shuhada binti Ahmad Shaupi | W16: A14E010F | X16: Fenomena Pengalaman Peniaga Golongan B40 dalam Persekitaran Mencabar-Pendemik Covid-19: Pendekatan Abduktif Logik | Y16: 16 Julai 2024 (Selasa) | Z16: 10.00 pagi | AA16: Platform Zoom (pautan akan dimaklumkan kemudian) | AB16: 1) Prof. Madya Dr. Anis Amira binti Ab Rahman (Penyelia Utama) | AC16: 2) Prof. Dr. Roslina binti Ahmad Saufi (Penyelia Bersama)
A17: 16 | C17: JUN | D17: Dr. Amira binti Jamil | E17: En. Zul Karami bin Che Musa | F17: Prof. Dr. Mohd Rafi bin Yaacob | G17: Dr. Mohd Rushdan bin Yasoa’ | H17: Fakulti Keusahawanan dan Perniagaan | N17: PENILAIAN CADANGAN PENYELIDIKAN (PROPOSAL DEFENSE) | O17: YBhg. Prof./Prof. Madya/Dr. | P17: YBhg. Prof./Prof. Madya/Dr. | Q17: Mesyuarat Jawatankuasa Pascasiswazah Bil. 5/2024 (kali ke-46) | S17: Penilaian Cadangan Penyelidikan (Proposal Defense) | T17: Doktor Falsafah | U17: Perakaunan | V17: Tippavan Rattanaprom | W17: A19E039F | X17: Factor That Influences the Accounting Practice Among SMEs: A Study on Southern Thai SMEs | Y17: 22 Julai 2024 (Isnin) | Z17: 10.00 pagi | AA17: Platform Zoom (pautan akan dimaklumkan kemudian) | AB17: 1) Prof. Dr. Mohd Nor Hakimin bin Yusof (Penyelia Utama) | AC17: 2) Prof. Madya Dr. Noorul Azwin binti Md Nasir (Penyelia Bersama)
A18: 17 | C18: JUN | D18: Dr. Azira Hanani binti Berahim @ Ab Rahman | E18: En. Zul Karami bin Che Musa | F18: Prof. Madya Dr. Dzulkifli bin Mukhtar | G18: Dr. Siti Fariha binti Muhamad | H18: Fakulti Keusahawanan dan Perniagaan | N18: PRA PEPERIKSAAN LISAN (PRE VIVA) | O18: YBrs. Prof. Madya/Dr. | P18: YBrs. Prof. Madya/Dr. | Q18: Mesyuarat Jawatankuasa Pascasiswazah Bil. 5/2024 (kali ke-46) | S18: Pra Peperiksaan Lisan (Pre Viva Voce) | T18: Doktor Falsafah | U18: Pengurusan | V18: Jia bin | W18: A22E011F | X18: The Effect of Principal-Agent Attributes and Firm Size on Budgetary Slack: Evidence from Manufacturing Listed Firms in China | Y18: 21 Julai 2024 (Ahad) | Z18: 10.00 pagi | AA18: Platform Zoom (pautan akan dimaklumkan kemudian) | AB18: 1) Prof. Madya Dr. Noorul Azwin binti Md Nasir (Penyelia Utama) | AC18: 2) Dr. Zaminor binti Zamzamir @ Zamzamin (Penyelia Bersama) | AD18: 3) Dr. Amira binti Jamil (Penyelia Bersama)
A19: 18 | C19: JUN | D19: Dr. Ahmad Ridhuwan bin Abdullah | E19: Dr. Nur Syakirah binti Ahmad | F19: Dr. Nik Syuhailah binti Nik Hussin | G19: Dr. Norhafifah binti Samsudin | H19: Fakulti Keusahawanan dan Perniagaan | N19: PRA PEPERIKSAAN LISAN (PRE VIVA) | O19: YBhg. Prof./Dr. | P19: YBhg. Prof./Dr. | Q19: Mesyuarat Jawatankuasa Pascasiswazah Bil. 5/2024 (kali ke-46) | S19: Pra Peperiksaan Lisan (Pre Viva Voce) | T19: Doktor Falsafah | U19: Pemasaran | V19: Siti Hanifa Sandri | W19: A19E0029F | X19: Brand Experience and Customer Relationship Marketing Towards Customer Based Brand Equity: Mediator Role of Word of Mouth in Budget Hotels | Y19: 14 Julai 2024 (Ahad) | Z19: 10.00 pagi | AA19: Platform Zoom (pautan akan dimaklumkan kemudian) | AB19: 1) Prof. Madya Dr. Noor Hasmini Hj Abd Ghani (Penyelia Utama)
A20: 19 | C20: JUN | D20: Dr. Rikinorhakis bin Ridzwan | E20: Dr. Norfazlirda binti Hairani | F20: Prof. Madya Dr. Wan Farha binti Wan Zulkiffli | G20: Dr. Nur Syakirah binti Ahmad | H20: Fakulti Keusahawanan dan Perniagaan | N20: PENILAIAN CADANGAN PENYELIDIKAN (PROPOSAL DEFENSE) | O20: YBrs. Prof. Madya/Dr. | P20: YBrs. Prof. Madya/Dr. | Q20: Mesyuarat Jawatankuasa Pascasiswazah Bil. 5/2024 (kali ke-46) | S20: Penilaian Cadangan Penyelidikan (Proposal Defense) | T20: Sarjana | U20: Pemasaran | V20: Amira Nur Syafiah binti Mohammad | W20: A21D053F | X20: Service Quality, Customer Satisfaction and Continuous Intention For Training Provider in East Coast Region | Y20: 15 Julai 2024 (Isnin) | Z20: 10.00 pagi | AA20: Platform Zoom (pautan akan dimaklumkan kemudian) | AB20: 1) Dr. Nik Syuhailah binti Hussin (Penyelia Utama) | AC20: 2) Puan Nadia Hanum binti Amiruddin (Penyelia Bersama)
A21: 20 | C21: JUN | D21: Dr. Siti Rohana binti Mohamad | E21: Dr. Muhammad Firdaus bin Zakaria | F21: Prof. Madya Dr. Hazriah binti Hasan | G21: Dr. Mohd Afifie bin Mohd Alwi | H21: Fakulti Keusahawanan dan Perniagaan | N21: PENILAIAN CADANGAN PENYELIDIKAN (PROPOSAL DEFENSE) | O21: YBrs. Prof. Madya/Dr. | P21: YBrs. Prof. Madya/Dr. | Q21: Mesyuarat Jawatankuasa Pascasiswazah Bil. 5/2024 (kali ke-46) | S21: Penilaian Cadangan Penyelidikan (Proposal Defense) | T21: Doktor Falsafah | U21: Perbankan dan Kewangan Islam | V21: Muhammad Lisman | W21: A19E0041F | X21: Indonesian Sharia Banking Transformation Model In The Digital Era | Y21: 24 Julai 2024 (Rabu) | Z21: 10.00 pagi | AA21: Platform Zoom (pautan akan dimaklumkan kemudian) | AB21: 1) Prof. Madya Dr. Mohd Zulkifli bin Muhammad (Penyelia Utama) | AC21: 2) Dr. Muhammad Zulfaris bin Mohd Salleh (Penyelia Bersama)
A22: 21 | C22: JUN | D22: Prof. Madya Dr. Azwan bin Abdullah | E22: Dr. Mohd Ikhwan bin Aziz | F22: Prof. Dr. Mohd Rafi bin Yaacob | G22: Prof. Madya Dr. Dzulkifli bin Mukhtar | H22: Fakulti Keusahawanan dan Perniagaan | N22: PENILAIAN CADANGAN PENYELIDIKAN (PROPOSAL DEFENSE) | O22: YBhg. Prof./Prof. Madya/Dr. | P22: YBhg. Prof./Prof. Madya/Dr. | Q22: Mesyuarat Jawatankuasa Pascasiswazah Bil. 5/2024 (kali ke-46) | S22: Penilaian Cadangan Penyelidikan (Proposal Defense) | T22: Doktor Falsafah | U22: Pengurusan | V22: Mohammad Firdaus bin Nizam | W22: A22E048F | X22: Leadership Style in Performance of Waqf at University Putra Malaysia (UPM) and Fatoni University (FU), Thailand : Exploratory Qualitative Case Study | Y22: 25 Julai 2024 (Khamis) | Z22: 10.00 pagi | AA22: Platform Zoom (pautan akan dimaklumkan kemudian) | AB22: 1) Prof. Dr. Balakrishnan a/l Parasuraman (Penyelia Utama) | AC22: 2) Prof. Madya Dr. Hazriah binti Hasan (Penyelia Bersama)
A23: 22 | C23: JULAI | D23: Dr. Syamsuriana binti Sidek | E23: Dr. Norhafifah binti Samsudin | F23: Prof. Madya Dr. Mohd Nazri bin Zakaria | G23: Dr. Hasannuddiin bin Hassan | H23: Fakulti Keusahawanan dan Perniagaan | N23: PRA PEPERIKSAAN LISAN (PRE VIVA VOCE) | O23: YBrs. Prof. Madya/Dr. | P23: YBrs. Prof. Madya/Dr. | Q23: Mesyuarat Jawatankuasa Pascasiswazah Bil. 6/2024 (kali ke-47) | S23: Pra Peperiksaan Lisan (Pre Viva Voce) | T23: Doktor Falsafah | U23: Keusahawanan | V23: Kuwata Muhammad Goni | W23: A20E0238F | X23: Green Human Resource Management, Green Innovation, and Environmental Performance of Hotel in Kano Nigeria: Moderating Role of Green Transformational Leadership | Y23: 4 Ogos 2024 (Ahad) | Z23: 10.00 pagi | AA23: Platform Zoom (pautan akan dimaklumkan kemudian) | AB23: 1) Dr. Shah Iskandar Fahmie bin Ramlee (Penyelia Utama) | AC23: 2) Dr. Tahirah binti Abdullah (Penyelia Bersama)
A24: 23 | C24: JULAI | D24: Dr. Mohd Ikhwan bin Aziz | E24: En. Ahmad Syakir bin Junoh @ Ismail | F24: Prof. Dr. Mohd Nor Hakimin bin Yusoff | G24: Dr. Nor Hafiza binti Othman | H24: Fakulti Keusahawanan dan Perniagaan | N24: PRA PEPERIKSAAN LISAN (PRE VIVA VOCE) | O24: YBhg. Prof. Dr./Dr. | P24: YBhg. Prof. Dr./Dr. | Q24: Mesyuarat Jawatankuasa Pascasiswazah Bil. 6/2024 (kali ke-47) | S24: Pra Peperiksaan Lisan (Pre Viva Voce) | T24: Doktor Falsafah | U24: Keusahawanan | V24: Rika Verawati | W24: A20E074F | X24: Minat Mahasiswa Dalam Bidang Pendidikan Keusahawanan Di Universiti PGRI Sumatera Barat | Y24: 6 Ogos 2024 (Selasa) | Z24: 10.00 pagi | AA24: Platform Zoom (pautan akan dimaklumkan kemudian) | AB24: 1) Prof. Dr. Mohd Rafi bin Yaacob (Penyelia Utama)
A25: 24 | C25: JULAI | D25: Dr. Ahmad Ridhuwan bin Abdullah | E25: Dr. Siti Fariha binti Muhamad | F25: Prof. Dr. Mohd Rafi bin Yaacob | G25: Prof. Madya Dr. Noorul Azwin binti Md Nasir | H25: Fakulti Keusahawanan dan Perniagaan | N25: PRA PEPERIKSAAN LISAN (PRE VIVA VOCE) | O25: YBhg. Prof. Dr./Prof. Madya/Dr. | P25: YBhg. Prof. Dr./Prof. Madya/Dr. | Q25: Mesyuarat Jawatankuasa Pascasiswazah Bil. 6/2024 (kali ke-47) | S25: Pra Peperiksaan Lisan (Pre Viva Voce) | T25: Doktor Falsafah | U25: Perakaunan | V25: Muhammad Ahyaruddin | W25: A19E0019F | X25: Institutional Isomorphism, Accountability and Local Government Performance in Riau Public Governance: Autonomy and Management Commitment as Moderating Variable | Y25: 7 Ogos 2024 (Rabu) | Z25: 10.00 pagi | AA25: Platform Zoom (pautan akan dimaklumkan kemudian) | AB25: 1) Prof. Dr. Mohd Nor Hakimin bin Yusoff (Penyelia Utama) | AC25: 2) Dr. Siti Afiqah binti Zainuddin (Penyelia Bersama) | AE25: Pengerusi - Prof. Madya Dr. Wan Farha binti Wan Zulkiffli (Tukar)
A26: 25 | C26: OGOS | D26: Dr. Syarizal bin Abdul Rahim | E26: Dr. Muhammad Zulfaris bin Mohd Salleh | F26: Dr. Ahmad Ridhuwan bin Abdullah | G26: Dr. Noor Raihani binti Zainol | H26: Fakulti Keusahawanan dan Perniagaan | N26: PENILAIAN SEMULA CADANGAN PENYELIDIKAN (re-PROPOSAL DEFENSE) | O26: YBrs. Dr. | P26: YBrs. Dr. | S26: Penilaian Semula Cadangan Penyelidikan (re-Proposal Defense) | T26: Doktor Falsafah | U26: Keusahawanan | V26: Sofia Samaalee | W26: A19E040F | X26: The Influence of Investing knowledge and behavioral factors towards the performance of individual investors in the trading shares of companies listed at The Stock Exchange, Thailand using investment decision making as a mediator | Y26: 5 September 2024 (Khamis) | Z26: 10.00 pagi | AA26: Platform Zoom (pautan akan dimaklumkan kemudian) | AB26: 1) Dr. Nur Ain Ayuni binti Sabri (Penyelia Utama) | AC26: 2) Dr. Azira Hanani binti Berahim @ Ab Rahman (Penyelia Bersama) | AD26: 3) Prof. Madya Dr. Dzulkifli bin Mukhtar (Penyelia Bersama) | AE26: Pen. Pengerusi - Dr. Muhammad Zulfaris bin Mohd Salleh (Tukar)
A27: 26 | C27: OGOS | D27: Dr. Hanieh Alipour Bazkiaei | E27: Dr. Nur Syafiqah binti A. Samad | F27: Dr. Noor Ullah Khan | G27: Prof. Madya Dr. Ng Siew Foen | H27: Fakulti Keusahawanan dan Perniagaan | N27: PENILAIAN CADANGAN PENYELIDIKAN (PROPOSAL DEFENSE) | O27: YBrs. Prof. Madya/Dr. | P27: YBrs. Prof. Madya/Dr. | Q27: Mesyuarat Jawatankuasa Pascasiswazah Bil. 7/2024 (kali ke-48) | S27: Penilaian Cadangan Penyelidikan (Proposal Defense) | T27: Sarjana Keusahawanan | U27: Pengurusan Sumber Manusia | V27: Thiiruchelvi a/p Gunasagaran | W27: A20D077P | X27: English as a Second Language (ESL) Teachers Preparedness Towards Students Achievements | Y27: 19 Ogos 2024 (Isnin) | Z27: 10.00 pagi | AA27: Platform Zoom (pautan akan dimaklumkan kemudian) | AB27: 1) Dr. P. Yukthamarani a/p Permarupan
A28: 27 | C28: OGOS | D28: Dr. Norfazlirda binti Hairani | E28: Pn. Nurul Hasliana binti Hamsani | F28: Dr. Nik Syuhailah binti Nik Hussin | G28: Dr. Nur Syakirah binti Ahmad | H28: Fakulti Keusahawanan dan Perniagaan | N28: PENILAIAN CADANGAN PENYELIDIKAN (PROPOSAL DEFENSE) | O28: YBrs. Dr. | P28: YBrs. Dr. | Q28: Mesyuarat Jawatankuasa Pascasiswazah Bil. 7/2024 (kali ke-48) | S28: Penilaian Cadangan Penyelidikan (Proposal Defense) | T28: Doktor Falsafah | U28: Pemasaran | V28: Shen Ke | W28: A21E049F | X28: The Impact of eWOM Characteristics on Intention to Travel to Destination Among Generation Z in China: Mediating by Attitude Towards Information Adoption | Y28: 22 September 2024 (Ahad) | Z28: 10.00 pagi | AA28: Platform Zoom (pautan akan dimaklumkan kemudian) | AB28: 1) Prof. Madya Dr. Wan Farha binti Wan Zulkiffli | AE28: Pengerusi - Dr. Nur Syakirah binti Ahmad (tukar) Panel 1 - Prof. Dr. Mohammad bin ismail (tukar)
A29: 28 | C29: OGOS | D29: Prof. Madya. Dr. Mohd Zulkifli bin Muhammad | E29: Dr. Amira binti Jamil | F29: Prof. Madya Dr. Anis Amira binti Ab Rahman | G29: Dr. Siti Salwani binti Abdullah | H29: Fakulti Keusahawanan dan Perniagaan | N29: PENILAIAN CADANGAN PENYELIDIKAN (PROPOSAL DEFENSE) | O29: YBrs. Prof. Madya/Dr. | P29: YBrs. Prof. Madya/Dr. | Q29: Mesyuarat Jawatankuasa Pascasiswazah Bil. 7/2024 (kali ke-48) | S29: Penilaian Cadangan Penyelidikan (Proposal Defense) | T29: Doktor Falsafah | U29: Keusahawanan | V29: Muhammad Umar | W29: A22E115F | X29: An Investigation of Innovation-Driven Enterprises Growth Strategies in the Newly Emerging Economy of Sub-Saharan Africa: A Nigerian Case Study | Y29: 20 Ogos 2024 (Selasa) | Z29: 10.00 pagi | AA29: Platform Zoom (pautan akan dimaklumkan kemudian) | AB29: 1) Prof. Madya Dr. Dzulkifli bin Mukhtar (Penyelia Utama) | AC29: 2) Dr. Mohd Ikhwan bin Aziz (Penyelia Bersama)
A30: 29 | C30: OGOS | D30: Dr. Tahirah binti Abdullah | E30: Dr. Tan Wai Hong | F30: Dr. Mohd Afifie bin Mohd Alwi | G30: Dr. Siti Rohana binti Mohamad | H30: Fakulti Keusahawanan dan Perniagaan | N30: PENILAIAN CADANGAN PENYELIDIKAN (PROPOSAL DEFENSE) | O30: YBrs. Dr. | P30: YBrs. Dr. | Q30: Mesyuarat Jawatankuasa Pascasiswazah Bil. 7/2024 (kali ke-48) | S30: Penilaian Cadangan Penyelidikan (Proposal Defense) | T30: Doktor Falsafah | U30: Kewangan | V30: Song Ziyan | W30: A21E016F | X30: The Effects of Empathy and the Moderating Role of Regulatory Focus on Donors Decision to Support Philanthropic Crowdfunding in China | Y30: 9 September 2024 (Isnin) | Z30: 10.00 pagi | AA30: Platform Zoom (pautan akan dimaklumkan kemudian) | AB30: 1) Dr. Ahmad Ridhuwan bin Abdullah (Penyelia Utama) | AC30: 2) Dr. Siti Salwani binti Abdullah (Penyelia Bersama) | AD30: 3) Dr. Nur Farahiah binti Azmi (Penyelia Bersama) | AE30: Pengerusi - Dr. Amira bintil Jamil (Tukar) Panel 1 - Prof. Madya Dr. Azwan bin Abdullah (tukar)
A31: 30 | C31: OGOS | D31: Dr. Hasannuddiin bin Hassan | F31: Prof. Dr. Balakrishnan a/l Parasuraman | G31: Prof. Dr. Mohd Nor Hakimin bin Yusoff | H31: Fakulti Keusahawanan dan Perniagaan | L31: SEMULA | N31: re-PROPOSAL DEFENSE | O31: YBhg. Prof./Dr. | P31: YBhg. Prof./Dr. | Q31: Mesyuarat Jawatankuasa Pascasiswazah Bil. 7/2024 (kali ke-48) | S31: re-Proposal Defence | T31: Doktor Falsafah | U31: Peruncitan | V31: Wan Ahmad Rizal bin Mohd Yusoff | W31: A19E026F | X31: A Study on Interpersonal Skills Among Selected Cases of Successful Malay Entrepreneurs Wholesale SMGs in Terengganu. | Y31: 25 Ogos 2024 (Ahad) | Z31: 10.00 pagi | AA31: Platform Zoom (pautan akan dimaklumkan kemudian) | AB31: 1) Prof. Dr. Mohd Rafi bin Yaacob (Penyelia Utama)
A32: 31 | C32: OGOS | D32: Dr. Siti Zamanira binti Mat Zaib | E32: Pn. Azizah binti Musa | F32: Prof. Madya Dr. Hazriah binti Hasan | G32: Dr. Aikal Liyani binti Mohd Rasdi | H32: Fakulti Keusahawanan dan Perniagaan | L32: SEMULA | N32: re-PROPOSAL DEFENSE | O32: YBrs. Prof. Madya/Dr. | P32: YBrs. Prof. Madya/Dr. | Q32: Mesyuarat Jawatankuasa Pascasiswazah Bil. 7/2024 (kali ke-48) | S32: re-Proposal Defence | T32: Doktor Falsafah | U32: Perdagangan | V32: Mizan Asnawi | W32: A19E0045F | X32: Examining the Readiness of SMEs in Implementing Halal Tourism in Indonesia: A Study using the Components Theory of Planned Behavior and Halal Tourism Literacy as Moderator | Y32: 25 Ogos 2024 (Ahad) | Z32: 10.00 pagi | AA32: Platform Zoom (pautan akan dimaklumkan kemudian) | AB32: 1) Dr. Siti Salwani binti Abdullah (Penyelia Utama)
A33: 32 | C33: OGOS | D33: Dr. Siti Rohana binti Mohamad | E33: En. Syed Azlan Aljaffree bin Syed Khadzil | F33: Prof. Madya Dr. Azwan bin Abdullah | G33: Dr. Siti Fariha binti Muhamad | H33: Fakulti Keusahawanan dan Perniagaan | L33: SEMULA | N33: re-PROPOSAL DEFENSE | O33: YBrs. Prof. Madya/Dr. | P33: YBrs. Prof. Madya/Dr. | Q33: Mesyuarat Jawatankuasa Pascasiswazah Bil. 7/2024 (kali ke-48) | S33: re-Proposal Defence | T33: Doktor Falsafah | U33: Kewangan | V33: Wen Peicheng | W33: A20E0201F | X33: Moderating Effects of USD Cycle and RMB Exchange Rate on Capital Market Linkage in China | Y33: 26 Ogos 2024 (Isnin) | Z33: 10.00 pagi | AA33: Platform Zoom (pautan akan dimaklumkan kemudian) | AB33: 1) Dr. Nurhaiza binti Nordin (Penyelia Utama) | AC33: 2) Dr Nurnaddia binti Nordin (Penyelia Bersama)
A34: 33 | C34: OGOS | D34: Dr. Tahirah binti Abdullah | F34: Dr. Mohd Rushdan bin Yasoa’ | G34: Dr. Siti Salwani binti Abdullah | H34: Fakulti Keusahawanan dan Perniagaan | N34: PRA PEPERIKSAAN LISAN (PRE VIVA VOCE) | O34: YBrs. Dr. | P34: YBrs. Dr. | S34: Pra Peperiksaan Lisan (Pre Viva Voce) | T34: Doktor Falsafah | U34: Perakaunan | V34: Evi Dwi Kartikasari | W34: A22E105F | X34: The Macro and Micro Organizational Elements and BUMDesa Performance in Indonesia: A Multiple Case Studies Approach | Y34: 5 Ogos 2024 (Isnin) | Z34: 2.30 petang | AA34: Platform Google Meet | AB34: 1) Dr. Siti Afiqah binti Zainuddin (Penyelia Utama) | AC34: 2) Dr. Amira binti Jamil (Penyelia Bersama)
A35: 34 | C35: OGOS | D35: Dr. Nur Syakirah binti Ahmad | E35: Puan Nadia Hanum binti Amiruddin | F35: Dr. Norhafifah binti Samsudin | G35: Dr. Norfazlirda binti Hairani | H35: Fakulti Keusahawanan dan Perniagaan | N35: PRA PEPERIKSAAN LISAN (PRE VIVA VOCE) | O35: YBrs. Dr./Puan | P35: YBrs. Dr./Puan | S35: Pra Peperiksaan Lisan (Pre Viva Voce) | T35: Sarjana Keusahawanan | U35: Pemasaran | V35: Zhuang Haimei | W35: A22D123F | X35: A Study on the Customer Purchase Intention Toward Colorkey Cosmetic Products In China | Y35: 13 Ogos 2024 (Selasa) | Z35: 10.00 pagi | AA35: Platform Zoom (pautan akan dimaklumkan kemudian) | AB35: 1) En. Mohammad Nizamuddin bin Abdul Rahim (Penyelia Utama)
A36: 35 | C36: OGOS | D36: Prof. Madya Dr. Muhammad Ashlyzan bin Razik | E36: Dr. Nur Syafiqah binti A. Samad | F36: Prof. Madya Dr. Noorul Azwin binti Md Nasir | G36: Prof. Dr. Mohd Rafi bin Yaacob | H36: Fakulti Keusahawanan dan Perniagaan | N36: PRA PEPERIKSAAN LISAN (PRE VIVA VOCE) | O36: YBhg. Prof./Prof. Madya/Dr. | P36: YBhg. Prof./Prof. Madya/Dr. | Q36: Mesyuarat Jawatankuasa Pascasiswazah Bil. 7/2024 (kali ke-48) | S36: Pra Peperiksaan Lisan (Pre Viva Voce) | T36: Doktor Falsafah | U36: Perakaunan | V36: Agustiawan | W36: A19E0011F | X36: Internal Audit Behavioral, Job Performance, and Audit Quality of Local Government In Riau Province | Y36: 12 Ogos 2024 (Isnin) | Z36: 2.30 petang | AA36: Platform Zoom (pautan akan dimaklumkan kemudian) | AB36: 1) Prof. Dr. Mohd Nor Hakimin bin Yusoff (Penyelia Utama) | AC36: 2) Dr. Tahirah binti Abdullah (Penyelia Bersama)
A37: 36 | C37: OKTOBER | D37: Dr. Shah Iskandar Fahmie bin Ramlee | E37: Dr. Siti Salwani binti Abdullah | F37: Prof. Dr. Mohd Rafi bin Yaacob | G37: Prof. Madya Ts. Dr. Zuraimi bin Abdul Aziz | H37: Fakulti Keusahawanan dan Perniagaan | N37: PRA PEPERIKSAAN LISAN (PRE VIVA VOCE) | O37: YBhg. Prof./Prof. Madya/Dr. | P37: YBhg. Prof./Prof. Madya/Dr. | Q37: Mesyuarat Jawatankuasa Pascasiswazah Bil. 7/2024 (kali ke-48) | S37: Pra Peperiksaan Lisan (Pre Viva Voce) | T37: Doktor Falsafah | U37: Pengurusan | V37: Azianis binti Mohd Noor | W37: A14E019F | X37: Organization Capital, Human Capital, Members Participation, Government Support and Co-operative Performance: Moderating Effect of Leadership | Y37: 21 Oktober 2024 (Isnin) | Z37: 10.00 pagi | AA37: Platform Zoom (pautan akan dimaklumkan kemudian) | AB37: 1) Prof. Dr. Mohammad bin Ismail (Penyelia Utama) | AC37: 2) Prof. Dr. Mohd Nor Hakimin bin Yusoff (Penyelia Bersama) | AE37: Pengerusi - Prof. Madya Dr. Dzulkifli bin Mukhtar (Tukar)
A38: 37 | C38: OGOS | D38: Dr. Kasmaruddin bin Che Hussin | E38: Dr. Siti Fariha binti Muhamad | F38: Prof. Dr. Mohd Rafi bin Yaacob | G38: Dr. Nor Hafiza binti Othman | H38: Fakulti Keusahawanan dan Perniagaan | N38: PRA PEPERIKSAAN LISAN (PRE VIVA VOCE) | O38: YBhg. Prof./Dr. | P38: YBhg. Prof./Dr. | Q38: Mesyuarat Jawatankuasa Pascasiswazah Bil. 7/2024 (kali ke-48) | S38: Pra Peperiksaan Lisan (Pre Viva Voce) | T38: Doktor Falsafah | U38: Keusahawanan | V38: Muhammad Nizam bin Zainuddin | W38: A19E056F | X38: The Development of Entrepreneurial Passion in the Identity Workspace of the Postgraduate Entrepreneurship Education Program | Y38: 10 September 2024 (Selasa) | Z38: 10.00 pagi | AA38: Platform Zoom (pautan akan dimaklumkan kemudian) | AB38: 1) Prof. Madya Dr. Dzulkifli bin Mukhtar (Penyelia Utama) | AC38: 2) Prof. Madya Dr. Anis Amira binti Ab Rahman (Penyelia Bersama) | AE38: Pengerusi - Prof. Madya Dr. Hazriah binti Hasan (Tukar) Pen. Pengerusi - Dr. Rikinorhakis bin Ridzwan (Tukar)
A39: 38 | C39: OGOS | D39: Dr. Azira Hanani binti Berahim @ Ab Rahman | F39: Prof. Madya Dr. Dzulkifli bin Mukhtar | G39: Dr. Tahirah binti Abdullah | H39: Fakulti Keusahawanan dan Perniagaan | N39: PRA PEPERIKSAAN LISAN (PRE VIVA VOCE) | O39: YBhg. Prof./Prof. Madya/Dr. | P39: YBhg. Prof. Madya/Dr. | S39: Pra Peperiksaan Lisan (Pre Viva Voce) | T39: Doktor Falsafah | U39: Perakaunan | V39: Linda Hetri Suriyanti | W39: A20E0183F | X39: The Mediating Effects of Innovation and a Dynamic Environment on the Link Between Strategic Management Accounting Techniques and Performance in Riau Manufacturing Companies | Y39: Akan ditentukan oleh penyelia | Z39: Akan ditentukan oleh penyelia | AA39: Akan ditentukan oleh penyelia | AB39: 1) Prof. Madya Dr. Noorul Azwin binti Md Nasir (Penyelia Utama) | AC39: 2) Dr. Siti Afiqah binti Zainuddin (Penyelia Bersama)
A40: 39 | C40: OGOS | D40: Dr. Wan Mohd Nazdrol bin Wan Mohd Nasir | E40: Dr. Suhaila binti Abdul Kadir | F40: Prof. Madya Dr. Wan Farha binti Wan Zulkiffli | G40: Dr. Nik Syuhailah binti Nik Hussin | H40: Fakulti Keusahawanan dan Perniagaan | N40: PRA PEPERIKSAAN LISAN (PRE VIVA VOCE) | O40: YBhg. Prof./Prof. Madya/Dr. | P40: YBhg. Prof. Madya/Dr. | S40: Pra Peperiksaan Lisan (Pre Viva Voce) | T40: Doktor Falsafah | U40: Pemasaran | V40: Wang Peijing | W40: A21E038F | X40: The Relationship Between Brand Image, Brand Attachment, Brand Hate and Brand Relationship Quality in Xiaomi Virtual Communities | Y40: 4 September 2024 (Rabu) | Z40: 9.30 pagi | AA40: Akan ditentukan oleh penyelia | AB40: 1) Prof. Madya Dr. Noor Hasmini binti Abd Ghani (Penyelia Utama) | AC40: 2) Dr. Nur Izzati binti Mohamad Anuar (Penyelia Bersama)
...

Sheet KEKERAPAN 
A1: KEKERAPAN PENSYARAH YANG TERLIBAT DENGAN PENILAIAN CADANGAN PENYELIDIKAN (PD) DAN PRA PEPERIKSAAN LISAN (CD)
A3: Bil | B3: Pensyarah | C3: TAHUN 2024 | H3: TAHUN 2025
C4: Pengerusi | D4: Penolong Pengerusi | E4: panel 1 | F4: panel 2 | G4: Jumlah Kekerapan | H4: Pengerusi | I4: Penolong Pengerusi | J4: panel 1 | K4: panel 2 | L4: Jumlah Kekerapan
A5: 1 | B5: Prof. Dr. Raja Suzana binti Raja Kasim | C5: =COUNTIF(DATA_SURAT_PELANTIKAN!$D$2:$D$56,B5) -> 0 | D5: =COUNTIF(DATA_SURAT_PELANTIKAN!$E$2:$E$56,B5) -> 0 | E5: =COUNTIF(DATA_SURAT_PELANTIKAN!$F$2:$F$56,B5) -> 2 | F5: =COUNTIF(DATA_SURAT_PELANTIKAN!$G$2:$G$56,B5) -> 0 | G5: =SUM(C5:F5) -> 2 | H5: =COUNTIF(DATA_SURAT_PELANTIKAN!$D$57:$D$150,B5) -> 0 | I5: =COUNTIF(DATA_SURAT_PELANTIKAN!$E$57:$E$150,B5) -> 0 | J5: =COUNTIF(DATA_SURAT_PELANTIKAN!$F$57:$F$150,B5) -> 3 | K5: =COUNTIF(DATA_SURAT_PELANTIKAN!$G$57:$G$150,B5) -> 0 | L5: =SUM(H5:K5) -> 3
A6: 2 | B6: Prof. Dr. Mohd Rafi bin Yaacob | C6: =COUNTIF(DATA_SURAT_PELANTIKAN!$D$2:$D$56,B6) -> 0 | D6: =COUNTIF(DATA_SURAT_PELANTIKAN!$E$2:$E$56,B6) -> 0 | E6: =COUNTIF(DATA_SURAT_PELANTIKAN!$F$2:$F$56,B6) -> 8 | F6: =COUNTIF(DATA_SURAT_PELANTIKAN!$G$2:$G$56,B6) -> 2 | G6: =SUM(C6:F6) -> 10 | H6: =COUNTIF(DATA_SURAT_PELANTIKAN!$D$57:$D$150,B6) -> 0 | I6: =COUNTIF(DATA_SURAT_PELANTIKAN!$E$57:$E$150,B6) -> 0 | J6: =COUNTIF(DATA_SURAT_PELANTIKAN!$F$57:$F$150,B6) -> 0 | K6: =COUNTIF(DATA_SURAT_PELANTIKAN!$G$57:$G$150,B6) -> 0 | L6: =SUM(H6:K6) -> 0
A7: 3 | B7: Prof. Dr. Balakrishnan A/L Parasuraman | C7: =COUNTIF(DATA_SURAT_PELANTIKAN!$D$2:$D$56,B7) -> 3 | D7: =COUNTIF(DATA_SURAT_PELANTIKAN!$E$2:$E$56,B7) -> 0 | E7: =COUNTIF(DATA_SURAT_PELANTIKAN!$F$2:$F$56,B7) -> 1 | F7: =COUNTIF(DATA_SURAT_PELANTIKAN!$G$2:$G$56,B7) -> 0 | G7: =SUM(C7:F7) -> 4 | H7: =COUNTIF(DATA_SURAT_PELANTIKAN!$D$57:$D$150,B7) -> 0 | I7: =COUNTIF(DATA_SURAT_PELANTIKAN!$E$57:$E$150,B7) -> 0 | J7: =COUNTIF(DATA_SURAT_PELANTIKAN!$F$57:$F$150,B7) -> 3 | K7: =COUNTIF(DATA_SURAT_PELANTIKAN!$G$57:$G$150,B7) -> 0 | L7: =SUM(H7:K7) -> 3
A8: 4 | B8: Prof. Dr. Mohd Nor Hakimin bin Yusoff | C8: =COUNTIF(DATA_SURAT_PELANTIKAN!$D$2:$D$56,B8) -> 0 | D8: =COUNTIF(DATA_SURAT_PELANTIKAN!$E$2:$E$56,B8) -> 0 | E8: =COUNTIF(DATA_SURAT_PELANTIKAN!$F$2:$F$56,B8) -> 4 | F8: =COUNTIF(DATA_SURAT_PELANTIKAN!$G$2:$G$56,B8) -> 1 | G8: =SUM(C8:F8) -> 5 | H8: =COUNTIF(DATA_SURAT_PELANTIKAN!$D$57:$D$150,B8) -> 0 | I8: =COUNTIF(DATA_SURAT_PELANTIKAN!$E$57:$E$150,B8) -> 0 | J8: =COUNTIF(DATA_SURAT_PELANTIKAN!$F$57:$F$150,B8) -> 5 | K8: =COUNTIF(DATA_SURAT_PELANTIKAN!$G$57:$G$150,B8) -> 1 | L8: =SUM(H8:K8) -> 6
A9: 5 | B9: Prof. Dr. Mohammad bin Ismail | C9: =COUNTIF(DATA_SURAT_PELANTIKAN!$D$2:$D$56,B9) -> 0 | D9: =COUNTIF(DATA_SURAT_PELANTIKAN!$E$2:$E$56,B9) -> 0 | E9: =COUNTIF(DATA_SURAT_PELANTIKAN!$F$2:$F$56,B9) -> 0 | F9: =COUNTIF(DATA_SURAT_PELANTIKAN!$G$2:$G$56,B9) -> 0 | G9: =SUM(C9:F9) -> 0 | H9: =COUNTIF(DATA_SURAT_PELANTIKAN!$D$57:$D$150,B9) -> 0 | I9: =COUNTIF(DATA_SURAT_PELANTIKAN!$E$57:$E$150,B9) -> 0 | J9: =COUNTIF(DATA_SURAT_PELANTIKAN!$F$57:$F$150,B9) -> 0 | K9: =COUNTIF(DATA_SURAT_PELANTIKAN!$G$57:$G$150,B9) -> 0 | L9: =SUM(H9:K9) -> 0
A10: 6 | B10: Prof. Madya Dr. Dzulkifli bin Mukhtar | C10: =COUNTIF(DATA_SURAT_PELANTIKAN!$D$2:$D$56,B10) -> 2 | D10: =COUNTIF(DATA_SURAT_PELANTIKAN!$E$2:$E$56,B10) -> 0 | E10: =COUNTIF(DATA_SURAT_PELANTIKAN!$F$2:$F$56,B10) -> 5 | F10: =COUNTIF(DATA_SURAT_PELANTIKAN!$G$2:$G$56,B10) -> 2 | G10: =SUM(C10:F10) -> 9 | H10: =COUNTIF(DATA_SURAT_PELANTIKAN!$D$57:$D$150,B10) -> 0 | I10: =COUNTIF(DATA_SURAT_PELANTIKAN!$E$57:$E$150,B10) -> 0 | J10: =COUNTIF(DATA_SURAT_PELANTIKAN!$F$57:$F$150,B10) -> 5 | K10: =COUNTIF(DATA_SURAT_PELANTIKAN!$G$57:$G$150,B10) -> 1 | L10: =SUM(H10:K10) -> 6
A11: 7 | B11: Prof. Madya. Dr. Mohd Zulkifli bin Muhammad | C11: =COUNTIF(DATA_SURAT_PELANTIKAN!$D$2:$D$56,B11) -> 4 | D11: =COUNTIF(DATA_SURAT_PELANTIKAN!$E$2:$E$56,B11) -> 0 | E11: =COUNTIF(DATA_SURAT_PELANTIKAN!$F$2:$F$56,B11) -> 0 | F11: =COUNTIF(DATA_SURAT_PELANTIKAN!$G$2:$G$56,B11) -> 0 | G11: =SUM(C11:F11) -> 4 | H11: =COUNTIF(DATA_SURAT_PELANTIKAN!$D$57:$D$150,B11) -> 5 | I11: =COUNTIF(DATA_SURAT_PELANTIKAN!$E$57:$E$150,B11) -> 0 | J11: =COUNTIF(DATA_SURAT_PELANTIKAN!$F$57:$F$150,B11) -> 5 | K11: =COUNTIF(DATA_SURAT_PELANTIKAN!$G$57:$G$150,B11) -> 1 | L11: =SUM(H11:K11) -> 11
A12: 8 | B12: Prof. Madya Dr. Mohd Nazri bin Zakaria | C12: =COUNTIF(DATA_SURAT_PELANTIKAN!$D$2:$D$56,B12) -> 2 | D12: =COUNTIF(DATA_SURAT_PELANTIKAN!$E$2:$E$56,B12) -> 0 | E12: =COUNTIF(DATA_SURAT_PELANTIKAN!$F$2:$F$56,B12) -> 2 | F12: =COUNTIF(DATA_SURAT_PELANTIKAN!$G$2:$G$56,B12) -> 2 | G12: =SUM(C12:F12) -> 6 | H12: =COUNTIF(DATA_SURAT_PELANTIKAN!$D$57:$D$150,B12) -> 2 | I12: =COUNTIF(DATA_SURAT_PELANTIKAN!$E$57:$E$150,B12) -> 0 | J12: =COUNTIF(DATA_SURAT_PELANTIKAN!$F$57:$F$150,B12) -> 4 | K12: =COUNTIF(DATA_SURAT_PELANTIKAN!$G$57:$G$150,B12) -> 0 | L12: =SUM(H12:K12) -> 6
A13: 9 | B13: Prof. Madya Dr. Wan Farha binti Wan Zulkiffli | C13: =COUNTIF(DATA_SURAT_PELANTIKAN!$D$2:$D$56,B13) -> 0 | D13: =COUNTIF(DATA_SURAT_PELANTIKAN!$E$2:$E$56,B13) -> 0 | E13: =COUNTIF(DATA_SURAT_PELANTIKAN!$F$2:$F$56,B13) -> 3 | F13: =COUNTIF(DATA_SURAT_PELANTIKAN!$G$2:$G$56,B13) -> 1 | G13: =SUM(C13:F13) -> 4 | H13: =COUNTIF(DATA_SURAT_PELANTIKAN!$D$57:$D$150,B13) -> 0 | I13: =COUNTIF(DATA_SURAT_PELANTIKAN!$E$57:$E$150,B13) -> 0 | J13: =COUNTIF(DATA_SURAT_PELANTIKAN!$F$57:$F$150,B13) -> 2 | K13: =COUNTIF(DATA_SURAT_PELANTIKAN!$G$57:$G$150,B13) -> 4 | L13: =SUM(H13:K13) -> 6
A14: 10 | B14: Prof. Madya Dr. Muhamad Saufi bin Che Rusuli | C14: =COUNTIF(DATA_SURAT_PELANTIKAN!$D$2:$D$56,B14) -> 1 | D14: =COUNTIF(DATA_SURAT_PELANTIKAN!$E$2:$E$56,B14) -> 0 | E14: =COUNTIF(DATA_SURAT_PELANTIKAN!$F$2:$F$56,B14) -> 2 | F14: =COUNTIF(DATA_SURAT_PELANTIKAN!$G$2:$G$56,B14) -> 1 | G14: =SUM(C14:F14) -> 4 | H14: =COUNTIF(DATA_SURAT_PELANTIKAN!$D$57:$D$150,B14) -> 1 | I14: =COUNTIF(DATA_SURAT_PELANTIKAN!$E$57:$E$150,B14) -> 0 | J14: =COUNTIF(DATA_SURAT_PELANTIKAN!$F$57:$F$150,B14) -> 3 | K14: =COUNTIF(DATA_SURAT_PELANTIKAN!$G$57:$G$150,B14) -> 0 | L14: =SUM(H14:K14) -> 4
A15: 11 | B15: Prof. Madya Dr. Noorshella Binti Che Nawi | C15: =COUNTIF(DATA_SURAT_PELANTIKAN!$D$2:$D$56,B15) -> 0 | D15: =COUNTIF(DATA_SURAT_PELANTIKAN!$E$2:$E$56,B15) -> 0 | E15: =COUNTIF(DATA_SURAT_PELANTIKAN!$F$2:$F$56,B15) -> 1 | F15: =COUNTIF(DATA_SURAT_PELANTIKAN!$G$2:$G$56,B15) -> 1 | G15: =SUM(C15:F15) -> 2 | H15: =COUNTIF(DATA_SURAT_PELANTIKAN!$D$57:$D$150,B15) -> 0 | I15: =COUNTIF(DATA_SURAT_PELANTIKAN!$E$57:$E$150,B15) -> 0 | J15: =COUNTIF(DATA_SURAT_PELANTIKAN!$F$57:$F$150,B15) -> 1 | K15: =COUNTIF(DATA_SURAT_PELANTIKAN!$G$57:$G$150,B15) -> 0 | L15: =SUM(H15:K15) -> 1
A16: 12 | B16: Prof. Madya Ts. Dr. Zuraimi bin Abdul Aziz | C16: =COUNTIF(DATA_SURAT_PELANTIKAN!$D$2:$D$56,B16) -> 0 | D16: =COUNTIF(DATA_SURAT_PELANTIKAN!$E$2:$E$56,B16) -> 0 | E16: =COUNTIF(DATA_SURAT_PELANTIKAN!$F$2:$F$56,B16) -> 0 | F16: =COUNTIF(DATA_SURAT_PELANTIKAN!$G$2:$G$56,B16) -> 2 | G16: =SUM(C16:F16) -> 2 | H16: =COUNTIF(DATA_SURAT_PELANTIKAN!$D$57:$D$150,B16) -> 0 | I16: =COUNTIF(DATA_SURAT_PELANTIKAN!$E$57:$E$150,B16) -> 0 | J16: =COUNTIF(DATA_SURAT_PELANTIKAN!$F$57:$F$150,B16) -> 2 | K16: =COUNTIF(DATA_SURAT_PELANTIKAN!$G$57:$G$150,B16) -> 0 | L16: =SUM(H16:K16) -> 2
... A85: 81 | B85: Dr. Nurul Fadzlyn binti Enche Nadzmy | C85: =COUNTIF(DATA_SURAT_PELANTIKAN!$D$2:$D$56,B85) -> 0 | D85: =COUNTIF(DATA_SURAT_PELANTIKAN!$E$2:$E$56,B85) -> 0 | E85: =COUNTIF(DATA_SURAT_PELANTIKAN!$F$2:$F$56,B85) -> 0 | F85: =COUNTIF(DATA_SURAT_PELANTIKAN!$G$2:$G$56,B85) -> 0 | G85: =SUM(C85:F85) -> 0 | H85: =COUNTIF(DATA_SURAT_PELANTIKAN!$D$57:$D$150,B85) -> 0 | I85: =COUNTIF(DATA_SURAT_PELANTIKAN!$E$57:$E$150,B85) -> 2 | J85: =COUNTIF(DATA_SURAT_PELANTIKAN!$F$57:$F$150,B85) -> 0 | K85: =COUNTIF(DATA_SURAT_PELANTIKAN!$G$57:$G$150,B85) -> 0 | L85: =SUM(H85:K85) -> 2
A86: 82 | B86: Dr Nurnaddia binti Nordin | C86: =COUNTIF(DATA_SURAT_PELANTIKAN!$D$2:$D$56,B86) -> 0 | D86: =COUNTIF(DATA_SURAT_PELANTIKAN!$E$2:$E$56,B86) -> 0 | E86: =COUNTIF(DATA_SURAT_PELANTIKAN!$F$2:$F$56,B86) -> 0 | F86: =COUNTIF(DATA_SURAT_PELANTIKAN!$G$2:$G$56,B86) -> 0 | G86: =SUM(C86:F86) -> 0 | H86: =COUNTIF(DATA_SURAT_PELANTIKAN!$D$57:$D$150,B86) -> 1 | I86: =COUNTIF(DATA_SURAT_PELANTIKAN!$E$57:$E$150,'KEKERAPAN '!B86) -> 1 | J86: =COUNTIF(DATA_SURAT_PELANTIKAN!$F$57:$F$150,B86) -> 0 | K86: =COUNTIF(DATA_SURAT_PELANTIKAN!$G$57:$G$150,B86) -> 0 | L86: =SUM(H86:K86) -> 2
A87: 83 | B87: Dr. Razman Hafifi bin Redzuan | C87: =COUNTIF(DATA_SURAT_PELANTIKAN!$D$2:$D$56,B87) -> 0 | D87: =COUNTIF(DATA_SURAT_PELANTIKAN!$E$2:$E$56,B87) -> 0 | E87: =COUNTIF(DATA_SURAT_PELANTIKAN!$F$2:$F$56,B87) -> 0 | F87: =COUNTIF(DATA_SURAT_PELANTIKAN!$G$2:$G$56,B87) -> 0 | G87: =SUM(C87:F87) -> 0 | H87: =COUNTIF(DATA_SURAT_PELANTIKAN!$D$57:$D$150,B87) -> 0 | I87: =COUNTIF(DATA_SURAT_PELANTIKAN!$E$57:$E$150,B87) -> 1 | J87: =COUNTIF(DATA_SURAT_PELANTIKAN!$F$57:$F$150,B87) -> 0 | K87: =COUNTIF(DATA_SURAT_PELANTIKAN!$G$57:$G$150,B87) -> 0 | L87: =SUM(H87:K87) -> 1
A88: 84 | B88: Dr. Nurhaiza binti Nordin | C88: =COUNTIF(DATA_SURAT_PELANTIKAN!$D$2:$D$56,B88) -> 0 | D88: =COUNTIF(DATA_SURAT_PELANTIKAN!$E$2:$E$56,B88) -> 0 | E88: =COUNTIF(DATA_SURAT_PELANTIKAN!$F$2:$F$56,B88) -> 0 | F88: =COUNTIF(DATA_SURAT_PELANTIKAN!$G$2:$G$56,B88) -> 0 | G88: =SUM(C88:F88) -> 0 | H88: =COUNTIF(DATA_SURAT_PELANTIKAN!$D$57:$D$150,B88) -> 1 | I88: =COUNTIF(DATA_SURAT_PELANTIKAN!$E$57:$E$150,B88) -> 1 | J88: =COUNTIF(DATA_SURAT_PELANTIKAN!$F$57:$F$150,B88) -> 0 | K88: =COUNTIF(DATA_SURAT_PELANTIKAN!$G$57:$G$150,B88) -> 2 | L88: =SUM(H88:K88) -> 4
A89: 85 | B89: Dr. Fatihah binti Mohd | C89: =COUNTIF(DATA_SURAT_PELANTIKAN!$D$2:$D$56,B89) -> 0 | D89: =COUNTIF(DATA_SURAT_PELANTIKAN!$E$2:$E$56,B89) -> 0 | E89: =COUNTIF(DATA_SURAT_PELANTIKAN!$F$2:$F$56,B89) -> 0 | F89: =COUNTIF(DATA_SURAT_PELANTIKAN!$G$2:$G$56,B89) -> 0 | G89: =SUM(C89:F89) -> 0 | H89: =COUNTIF(DATA_SURAT_PELANTIKAN!$D$57:$D$150,B89) -> 1 | I89: =COUNTIF(DATA_SURAT_PELANTIKAN!$E$57:$E$150,B89) -> 0 | J89: =COUNTIF(DATA_SURAT_PELANTIKAN!$F$57:$F$150,B89) -> 0 | K89: =COUNTIF(DATA_SURAT_PELANTIKAN!$G$57:$G$150,B89) -> 1 | L89: =SUM(H89:K89) -> 2
A90: 86 | B90: En. Mohammad Nizamuddin bin Abdul Rahim | C90: =COUNTIF(DATA_SURAT_PELANTIKAN!$D$2:$D$56,B90) -> 0 | D90: =COUNTIF(DATA_SURAT_PELANTIKAN!$E$2:$E$56,B90) -> 0 | E90: =COUNTIF(DATA_SURAT_PELANTIKAN!$F$2:$F$56,B90) -> 0 | F90: =COUNTIF(DATA_SURAT_PELANTIKAN!$G$2:$G$56,B90) -> 0 | G90: =SUM(C90:F90) -> 0 | H90: =COUNTIF(DATA_SURAT_PELANTIKAN!$D$57:$D$150,B90) -> 0 | I90: =COUNTIF(DATA_SURAT_PELANTIKAN!$E$57:$E$150,B90) -> 1 | J90: =COUNTIF(DATA_SURAT_PELANTIKAN!$F$57:$F$150,B90) -> 0 | K90: =COUNTIF(DATA_SURAT_PELANTIKAN!$G$57:$G$150,B90) -> 0 | L90: =SUM(H90:K90) -> 1
A91: 87 | B91: Dr. Farah Hanan binti Muhamad | C91: =COUNTIF(DATA_SURAT_PELANTIKAN!$D$2:$D$56,B91) -> 0 | D91: =COUNTIF(DATA_SURAT_PELANTIKAN!$E$2:$E$56,B91) -> 0 | E91: =COUNTIF(DATA_SURAT_PELANTIKAN!$F$2:$F$56,B91) -> 0 | F91: =COUNTIF(DATA_SURAT_PELANTIKAN!$G$2:$G$56,B91) -> 0 | G91: =SUM(C91:F91) -> 0 | H91: =COUNTIF(DATA_SURAT_PELANTIKAN!$D$57:$D$150,B91) -> 0 | I91: =COUNTIF(DATA_SURAT_PELANTIKAN!$E$57:$E$150,B91) -> 2 | J91: =COUNTIF(DATA_SURAT_PELANTIKAN!$F$57:$F$150,B91) -> 0 | K91: =COUNTIF(DATA_SURAT_PELANTIKAN!$G$57:$G$150,B91) -> 0 | L91: =SUM(H91:K91) -> 2
A92: 88 | B92: Dr. Mardhiah binti Kamaruddin | C92: =COUNTIF(DATA_SURAT_PELANTIKAN!$D$2:$D$56,B92) -> 0 | D92: =COUNTIF(DATA_SURAT_PELANTIKAN!$E$2:$E$56,B92) -> 0 | E92: =COUNTIF(DATA_SURAT_PELANTIKAN!$F$2:$F$56,B92) -> 0 | F92: =COUNTIF(DATA_SURAT_PELANTIKAN!$G$2:$G$56,B92) -> 0 | G92: =SUM(C92:F92) -> 0 | H92: =COUNTIF(DATA_SURAT_PELANTIKAN!$D$57:$D$150,B92) -> 0 | I92: =COUNTIF(DATA_SURAT_PELANTIKAN!$E$57:$E$150,B92) -> 0 | J92: =COUNTIF(DATA_SURAT_PELANTIKAN!$F$57:$F$150,B92) -> 0 | K92: =COUNTIF(DATA_SURAT_PELANTIKAN!$G$57:$G$150,B92) -> 1 | L92: =SUM(H92:K92) -> 1
A93: 89 | B93: Dr. Siti Amaliya binti Mohd Radyi | C93: =COUNTIF(DATA_SURAT_PELANTIKAN!$D$2:$D$56,B93) -> 0 | D93: =COUNTIF(DATA_SURAT_PELANTIKAN!$E$2:$E$56,B93) -> 0 | E93: =COUNTIF(DATA_SURAT_PELANTIKAN!$F$2:$F$56,B93) -> 0 | F93: =COUNTIF(DATA_SURAT_PELANTIKAN!$G$2:$G$56,B93) -> 0 | G93: =SUM(C93:F93) -> 0 | H93: =COUNTIF(DATA_SURAT_PELANTIKAN!$D$57:$D$150,B93) -> 0 | I93: =COUNTIF(DATA_SURAT_PELANTIKAN!$E$57:$E$150,B93) -> 1 | J93: =COUNTIF(DATA_SURAT_PELANTIKAN!$F$57:$F$150,B93) -> 0 | K93: =COUNTIF(DATA_SURAT_PELANTIKAN!$G$57:$G$150,B93) -> 0 | L93: =SUM(H93:K93) -> 1
A94: 90 | B94: Dr. Nur A’mira binti Mohd Yaziz | C94: =COUNTIF(DATA_SURAT_PELANTIKAN!$D$2:$D$56,B94) -> 0 | D94: =COUNTIF(DATA_SURAT_PELANTIKAN!$E$2:$E$56,B94) -> 0 | E94: =COUNTIF(DATA_SURAT_PELANTIKAN!$F$2:$F$56,B94) -> 0 | F94: =COUNTIF(DATA_SURAT_PELANTIKAN!$G$2:$G$56,B94) -> 0 | G94: =SUM(C94:F94) -> 0 | H94: =COUNTIF(DATA_SURAT_PELANTIKAN!$D$57:$D$150,B94) -> 0 | I94: =COUNTIF(DATA_SURAT_PELANTIKAN!$E$57:$E$150,B94) -> 1 | J94: =COUNTIF(DATA_SURAT_PELANTIKAN!$F$57:$F$150,B94) -> 0 | K94: =COUNTIF(DATA_SURAT_PELANTIKAN!$G$57:$G$150,B94) -> 0 | L94: =SUM(H94:K94) -> 1
A95: 91 | B95: Dr. Muhammad Pirdaus bin Yusoh | C95: =COUNTIF(DATA_SURAT_PELANTIKAN!$D$2:$D$56,B95) -> 0 | D95: =COUNTIF(DATA_SURAT_PELANTIKAN!$E$2:$E$56,B95) -> 0 | E95: =COUNTIF(DATA_SURAT_PELANTIKAN!$F$2:$F$56,B95) -> 0 | F95: =COUNTIF(DATA_SURAT_PELANTIKAN!$G$2:$G$56,B95) -> 0 | G95: =SUM(C95:F95) -> 0 | H95: =COUNTIF(DATA_SURAT_PELANTIKAN!$D$57:$D$150,B95) -> 0 | I95: =COUNTIF(DATA_SURAT_PELANTIKAN!$E$57:$E$150,B95) -> 0 | J95: =COUNTIF(DATA_SURAT_PELANTIKAN!$F$57:$F$150,B95) -> 0 | K95: =COUNTIF(DATA_SURAT_PELANTIKAN!$G$57:$G$150,B95) -> 0
A96: 92 | B96: Dr. Siti Amirah binti Ahmad Tarmizi | C96: =COUNTIF(DATA_SURAT_PELANTIKAN!$D$2:$D$56,B96) -> 0 | D96: =COUNTIF(DATA_SURAT_PELANTIKAN!$E$2:$E$56,B96) -> 0 | E96: =COUNTIF(DATA_SURAT_PELANTIKAN!$F$2:$F$56,B96) -> 0 | F96: =COUNTIF(DATA_SURAT_PELANTIKAN!$G$2:$G$56,B96) -> 0 | G96: =SUM(C96:F96) -> 0 | H96: =COUNTIF(DATA_SURAT_PELANTIKAN!$D$57:$D$150,B96) -> 0 | I96: =COUNTIF(DATA_SURAT_PELANTIKAN!$E$57:$E$150,B96) -> 0 | J96: =COUNTIF(DATA_SURAT_PELANTIKAN!$F$57:$F$150,B96) -> 0 | K96: =COUNTIF(DATA_SURAT_PELANTIKAN!$G$57:$G$150,B96) -> 0
A97: 93 | B97: Dr. Mohd Shahril Nizam bin Md Radzi | C97: =COUNTIF(DATA_SURAT_PELANTIKAN!$D$2:$D$56,B97) -> 0 | D97: =COUNTIF(DATA_SURAT_PELANTIKAN!$E$2:$E$56,B97) -> 0 | E97: =COUNTIF(DATA_SURAT_PELANTIKAN!$F$2:$F$56,B97) -> 0 | F97: =COUNTIF(DATA_SURAT_PELANTIKAN!$G$2:$G$56,B97) -> 0 | G97: =SUM(C97:F97) -> 0 | H97: =COUNTIF(DATA_SURAT_PELANTIKAN!$D$57:$D$150,B97) -> 0 | I97: =COUNTIF(DATA_SURAT_PELANTIKAN!$E$57:$E$150,B97) -> 0 | J97: =COUNTIF(DATA_SURAT_PELANTIKAN!$F$57:$F$150,B97) -> 0 | K97: =COUNTIF(DATA_SURAT_PELANTIKAN!$G$57:$G$150,B97) -> 0
A98: 94 | B98: Prof. Madya Dr. Mohd Zain bin Mubarak | C98: =COUNTIF(DATA_SURAT_PELANTIKAN!$D$2:$D$56,B98) -> 0 | D98: =COUNTIF(DATA_SURAT_PELANTIKAN!$E$2:$E$56,B98) -> 0 | E98: =COUNTIF(DATA_SURAT_PELANTIKAN!$F$2:$F$56,B98) -> 0 | F98: =COUNTIF(DATA_SURAT_PELANTIKAN!$G$2:$G$56,B98) -> 0 | G98: =SUM(C98:F98) -> 0 | H98: =COUNTIF(DATA_SURAT_PELANTIKAN!$D$57:$D$150,B98) -> 0 | I98: =COUNTIF(DATA_SURAT_PELANTIKAN!$E$57:$E$150,B98) -> 0 | J98: =COUNTIF(DATA_SURAT_PELANTIKAN!$F$57:$F$150,B98) -> 0 | K98: =COUNTIF(DATA_SURAT_PELANTIKAN!$G$57:$G$150,B98) -> 0
A99: 95 | B99: Dr. Yukhtamarani a/p Permarupan | C99: =COUNTIF(DATA_SURAT_PELANTIKAN!$D$2:$D$56,B99) -> 0 | D99: =COUNTIF(DATA_SURAT_PELANTIKAN!$E$2:$E$56,B99) -> 0 | E99: =COUNTIF(DATA_SURAT_PELANTIKAN!$F$2:$F$56,B99) -> 0 | F99: =COUNTIF(DATA_SURAT_PELANTIKAN!$G$2:$G$56,B99) -> 0 | G99: =SUM(C99:F99) -> 0 | H99: =COUNTIF(DATA_SURAT_PELANTIKAN!$D$57:$D$150,B99) -> 0 | I99: =COUNTIF(DATA_SURAT_PELANTIKAN!$E$57:$E$150,B99) -> 0 | J99: =COUNTIF(DATA_SURAT_PELANTIKAN!$F$57:$F$150,B99) -> 0 | K99: =COUNTIF(DATA_SURAT_PELANTIKAN!$G$57:$G$150,B99) -> 0
A100: 96 | B100: Prof. Dr. Naresh Kumar a/l Samy | C100: =COUNTIF(DATA_SURAT_PELANTIKAN!$D$2:$D$56,B100) -> 0 | D100: =COUNTIF(DATA_SURAT_PELANTIKAN!$E$2:$E$56,B100) -> 0 | E100: =COUNTIF(DATA_SURAT_PELANTIKAN!$F$2:$F$56,B100) -> 0 | F100: =COUNTIF(DATA_SURAT_PELANTIKAN!$G$2:$G$56,B100) -> 0 | G100: =SUM(C100:F100) -> 0 | H100: =COUNTIF(DATA_SURAT_PELANTIKAN!$D$57:$D$150,B100) -> 0 | I100: =COUNTIF(DATA_SURAT_PELANTIKAN!$E$57:$E$150,B100) -> 0 | J100: =COUNTIF(DATA_SURAT_PELANTIKAN!$F$57:$F$150,B100) -> 0 | K100: =COUNTIF(DATA_SURAT_PELANTIKAN!$G$57:$G$150,B100) -> 0
G101: =SUM(G5:G91) -> 213
